Workbook

Sheet RFQ
B2: NKORR Technologies Pvt Ltd Assets : 2025-26
A3: Address | B3: NKORR TECHNOLOGIES PRIVATE LTD 1D CARNIVAL BUILDING, TECHNO PARK, TRIVANDRUM, KERALA- 695581
A4: Policy Type Required | B4: Electronic Software Development Unit/s
A6: Policy Type | C6: Sum Insured
C7: TVM | D7: Kochi | F7: Total Sum Insured
A8: Sookshma Udyam Suraksha (SFSP incl.EQ, STFI and Terrorism) | C8: =SUM('Workstn and Glass TVM'!E38,'Workstn and Glass TVM'!E57,'Lights and Fitting TVM'!E58,'Other Assets Items TVM'!D24) -> 2523803.5 | D8: =SUM('Workstn and Glass Kochi'!E10,'Workstn and Glass Kochi'!E21,'Workstn and Glass Kochi'!E31,'Light and Fitting Kochi'!F15,'Other Assets Kochi'!E44) -> 2142930 | F8: =SUM(C8:D8) -> 4666733.5
A9: Burglary with Theft | C9: =SUM('Workstn and Glass TVM'!F38,'Workstn and Glass TVM'!F57,'Lights and Fitting TVM'!F58,'Other Assets Items TVM'!E24) -> 2523803.5 | D9: =SUM('Workstn and Glass Kochi'!F10,'Workstn and Glass Kochi'!F21,'Workstn and Glass Kochi'!F31,'Light and Fitting Kochi'!G15,'Other Assets Kochi'!F44) -> 2142930 | F9: =SUM(C9:D9) -> 4666733.5
A10: Plate Glass (Inluding Fire) | C10: =SUM('Workstn and Glass TVM'!E38,'Workstn and Glass TVM'!E57) -> 1892080.4 | D10: =SUM('Workstn and Glass Kochi'!E31) -> 473700 | F10: =SUM(C10:D10) -> 2365780.5
A11: Electronic Equipment Insurance | C11: =SUM('Lights and Fitting TVM'!G58,'Laptops and Monitor TVM'!J69,'Other Assets Items TVM'!F24) -> 1590709 | D11: =SUM('Light and Fitting Kochi'!H15,'Laptops and Monitors kochi'!I35,'Other Assets Kochi'!G44) -> 869065.96 | F11: =SUM(C11:D11) -> 2459774.9
A12: All Risk Portable Electronic Equipment Insurance (incluiding mechanical, electrical breakdown, Buglary and Theft) | C12: =SUM('Laptops and Monitor TVM'!E76) -> 5087116 | D12: =SUM('Laptops and Monitors kochi'!E32) -> 2056196 | F12: =SUM(C12:D12) -> 7143312
A13: Mechanical Breakdown | C13: =SUM('Other Assets Items TVM'!G24) -> 99898 | D13: =SUM('Other Assets Kochi'!H44) -> 727926 | F13: =SUM(C13:D13) -> 827824
D15: Total | F15: =SUM(F8:F13) -> 22130158
A16: *Note: Values taken as on reinstatement basis

Sheet Workstn and Glass Kochi
B1: Chair
A2: Sl No | B2: Description | C2: Quantity | D2: Value | E2: Fire | F2: Burglary
A3: 1 | B3: Workstation Chairs No. | C3: 40 | D3: 1,98,800 | E3: =D3 -> 1,98,800 | F3: =D3 -> 1,98,800
A4: 2 | B4: Pantry Chairs No | C4: 8 | D4: 28880 | E4: =D4 -> 28880 | F4: =D4 -> 28880
A5: 3 | B5: Foosball Board | C5: 1 | D5: 50000 | E5: =D5 -> 50000 | F5: =D5 -> 50000
A6: 4 | B6: Furniture (Sofa set) | C6: 1 | D6: 45000 | E6: =D6 -> 45000 | F6: =D6 -> 45000
A7: 5 | B7: PLB Big shelfs with small shelfs | C7: 3 | D7: 35000 | E7: =D7 -> 35000 | F7: =D7 -> 35000
A8: 6 | B8: Indoor Plants box | C8: 3 | D8: 26000 | E8: =D8 -> 26000 | F8: =D8 -> 26000
A9: 7 | B9: PLB umberla stand and helmet Rack | C9: 1 | D9: 75800 | E9: =D9 -> 75800 | F9: =D9 -> 75800
D10: Total | E10: =SUM(E3:E9) -> 260680 | F10: =SUM(F3:F9) -> 260680
A12: Tables
A13: Sl No | B13: Description | C13: Quantity | D13: Value
A14: 1 | B14: Linear Workstations | C14: 28 | D14: 198800 | E14: =D14 -> 198800 | F14: =D14 -> 198800
A15: 2 | B15: Table for booth | C15: 2 | D15: 26350 | E15: =D15 -> 26350 | F15: =D15 -> 26350
A16: 3 | B16: Pantry table | C16: 1 | D16: 7980 | E16: =D16 -> 7980 | F16: =D16 -> 7980
B17: Table for with side storage | C17: 1 | D17: 21989 | E17: =D17 -> 21989 | F17: =D17 -> 21989
A18: 4 | B18: Table for booth | C18: 1 | D18: 5000 | E18: =D18 -> 5000 | F18: =D18 -> 5000
D19: Total | E19: =SUM(E14:E18) -> 260119 | F19: =SUM(F14:F18) -> 260119
B21: Total | E21: =SUM(E10,E19) -> 520799 | F21: =SUM(F10,F19) -> 520799
A23: Glass Items
A24: Sl No | B24: Description | C24: Quantity | D24: Value
A25: 1 | B25: Glass wall | C25: 334 sqf | D25: 133600 | E25: =D25 -> 133600 | F25: =D25 -> 133600
A26: 2 | B26: Glass single Swing door | C26: 3 | D26: 79500 | E26: =D26 -> 79500 | F26: =D26 -> 79500
A27: 3 | B27: Toughened glass Double Swing door | C27: 1 | D27: 52000 | E27: =D27 -> 52000 | F27: =D27 -> 52000
A28: 4 | B28: Other doors | C28: 6 | D28: 60600 | E28: =D28 -> 60600 | F28: =D28 -> 60600
A29: 5 | B29: Wooden Doors | C29: 8 | D29: 148000 | E29: =D29 -> 148000 | F29: =D29 -> 148000
B31: Total | E31: =SUM(E25:E30) -> 473700 | F31: =SUM(F25:F30) -> 473700

Sheet Workstn and Glass TVM
B1: Work Stations Description | C1: Quantity | D1: Amount | E1: Fire | F1: Burglary
A2: 1 | B2: LINEAR work stations of size 1200mm (W )x 600mm (D) x 750mm (H) | C2: 23 | D2: 187335 | E2: =D2 -> 187335 | F2: =D2 -> 187335
A4: 2 | B4: LINEAR work stations of size 1350mm (W )x 600mm (D)
B5: x 750mm (H) | C5: 3 | D5: 34350 | E5: =D5 -> 34350 | F5: =D5 -> 34350
A6: 3 | B6: Table at Call booth -900mm (W) x 600mm (D) x 750mm | C6: 2 | D6: 27610 | E6: =D6 -> 27610 | F6: =D6 -> 27610
A7: 4 | B7: Cabin table of size1500mm (W )x 750mm (D) x 750mm
B8: (H) with side storage of 1200mm (W )x 450mm (D) x
B9: 750mm(H) | C9: 1 | D9: 27260 | E9: =D9 -> 27260 | F9: =D9 -> 27260
A10: 5 | B10: Meeting Room Table of Size:- 2100mm(W) x 900mm(D) x
B11: 750mm(H) with 2 No. flip up
C12: 1 | D12: 27375 | E12: =D12 -> 27375 | F12: =D12 -> 27375
A13: 6 | B13: Low Height Storage- Size:- 7200mm(W) x 450mm(D) x
B14: 900mm (H) | C14: 1 | D14: 76440 | E14: =D14 -> 76440 | F14: =D14 -> 76440
A16: 7 | B16: Low Height Storage- Size:- 16500mm(W) x 450mm(D) x
B17: 900mm (H) | C17: 1 | D17: 14065 | E17: =D17 -> 14065 | F17: =D17 -> 14065
A19: 8 | B19: Medium Height Storage- Size:- 1200mm(W) x 450mm(D) | C19: 1
B20: x 1200mm (H) | D20: 15465 | E20: =D20 -> 15465 | F20: =D20 -> 15465
A22: 9 | B22: Full Height Storage- Size:- 1500mm(W) x 450mm(D) x
B23: 2100mm (H) | C23: 1 | D23: 33770 | E23: =D23 -> 33770 | F23: =D23 -> 33770
A25: 10 | B25: Full Height Storage- Size:- 1050mm(W) x 450mm(D) x
B26: 2100mm (H) | C26: 1 | D26: 23600 | E26: =D26 -> 23600 | F26: =D26 -> 23600
A29: 11 | B29: LINEAR work stations of size 1200mm (W )x 600mm (D) x 750mm (H)
C30: 38 | D30: 320720 | E30: =D30 -> 320720 | F30: =D30 -> 320720
A32: 12 | B32: Swing door storage 1800L x 450D x 1200ht | C32: 1 | D32: 27805 | E32: =D32 -> 27805 | F32: =D32 -> 27805
A33: 13 | B33: Trainer Table 1200L x 600D x 750ht | C33: 1 | D33: 9510 | E33: =D33 -> 9510 | F33: =D33 -> 9510
A34: 14 | B34: L shape swing door storage 2550+900L x 450D x 2400ht | C34: 1 | D34: 108570 | E34: =D34 -> 108570 | F34: =D34 -> 108570
A35: 15 | B35: WORK STATIONS | C35: 5 | D35: 53965 | E35: =D35 -> 53965 | F35: =D35 -> 53965
E38: =SUM(E2:E37) -> 987840 | F38: =SUM(F2:F37) -> 987840
B42: Glass Partitions Description | C42: Quantity | D42: Amount | E42: Fire | F42: Burglary
A44: 1 | B44: Full Glass Partitions | C44: 24.21 | D44: 185085.45 | E44: =D44 -> 185085.45 | F44: =D44 -> 185085.45
A46: 2 | B46: DOORS
A47: 3 | B47: (i) shutter size- 90cmx 240 cm. | C47: 5 | D47: 236925 | E47: =D47 -> 236925 | F47: =D47 -> 236925
A48: 4 | B48: (ii) shutter size- 80cmx 240 cm. | C48: 2 | D48: 89730 | E48: =D48 -> 89730 | F48: =D48 -> 89730
A49: 5 | B49: (iii) shutter size- 100cmx 240 cm. | C49: 1 | D49: 50055 | E49: =D49 -> 50055 | F49: =D49 -> 50055
A50: 6 | B50: (iv) shutter size- 110cmx 240 cm. | C50: 1 | D50: 52580 | E50: =D50 -> 52580 | F50: =D50 -> 52580
A51: 7 | B51: (v) Entrance door-double shutter of size- 188cmx 196 cm. | C51: 1 | D51: 95060 | E51: =D51 -> 95060 | F51: =D51 -> 95060
A52: 8 | B52: (vi)Supply and fixing of Handles of size 32mm x 1000mm | E52: =D52 -> 0 | F52: =D52 -> 0
A53: 9 | B53: (Geze ID no.98163105) for entrance doors. | C53: 2 | D53: 22670 | E53: =D53 -> 22670 | F53: =D53 -> 22670
A54: 10 | B54: (i)size of the shutter is 80cmx 240 cm. | C54: 2 | D54: 50250 | E54: =D54 -> 50250 | F54: =D54 -> 50250
A55: 11 | B55: (i)size of the opening 90cmx 240 cm. | C55: 1 | D55: 32220 | E55: =D55 -> 32220 | F55: =D55 -> 32220
...

Sheet Lights and Fitting TVM
B1: Wipro LED Lights Description | C1: Quantity | D1: Amount | E1: Fire | F1: Burglary | G1: EEI
B2: Supply and installation of WIPRO make LINEOS LED/LM
B3: 22 40W /20W Linear suspended luminaire,
A4: 1 | B4: (i)WIPRO Product Cat No.LM22-501-XXX-57-WX from
B5: existing rcc roof to +270cm. | C5: 4 | D5: 28780 | E5: 28780 | F5: 28780
A6: 2 | B6: (ii) WIPRO Product Cat No.LM22-251-XXX-57-WX from
B7: existing rcc roof to +270cm | C7: 13 | D7: 54340 | E7: 54340 | F7: 54340
A8: 3 | B8: WIPRO Product Cat No.LM29-451-XXX 57-XX along with
B9: Frame 9180PO1089-LP | C9: 2 | D9: 14830 | E9: 14830 | F9: 14830
A10: 4 | B10: WIPRO Product Cat No.LD80-350-XXX-60-XX :- 6W | C10: 6 | D10: 3810 | E10: 3810 | F10: 3810
A11: 5 | B11: WIPRO Product Cat No.LD80-530-XXX-60-XX :- 9W | C11: 3 | D11: 2295 | E11: 2295 | F11: 2295
A12: 6 | B12: WIPRO Product Cat No.LD80-101-XXX-60-XX :- 12W | C12: 6 | D12: 5250 | E12: 5250 | F12: 5250
A13: 7 | B13: WIPRO Product Cat No.LD80-131-XXX-60-XX :- 15W | C13: 2 | D13: 1960 | E13: 1960 | F13: 1960
A14: 8 | B14: WIPRO Product Cat No.LD80-171-XXX-60-XX :- 18W | C14: 2 | D14: 2200 | E14: 2200 | F14: 2200
A15: 9 | B15: WIPRO Product Cat No.LD30-201-36W-40-PL(330mm) :-
B16: 20W | C16: 7 | D16: 23695 | E16: 23695 | F16: 23695 | G16: =D16 -> 23695
A17: 10 | B17: WIPRO Product Cat No.LD30-101-36W-40-PL(330mm) :-
B18: 10W | C18: 2 | D18: 6480 | E18: 6480 | F18: 6480
A19: 11 | B19: WIPRO Product Cat No.LD99-151--XX57SMWH-12W | C19: 13 | D19: 31070 | E19: 31070 | F19: 31070 | G19: =D19 -> 31070
A20: 12 | B20: WIPRO Product Cat No.LD99-211--XX57SMWH-15W | C20: 6 | D20: 14490 | E20: 14490 | F20: 14490 | G20: =D20 -> 14490
A21: 13 | B21: Product Cat No.LS06-015-120-WH-50 :- 15W & LG40-078 | C21: 3 | D21: 12300 | E21: 12300 | F21: 12300 | G21: =D21 -> 12300
B23: Supply and installation of Pasolite make pendant along
B24: with E-27 holder and lamp
A25: 14 | B25: Pasolite Product Cat No.PD001, 350mm dia/H-320 mm | C25: 8 | D25: 30440 | E25: 30440 | F25: 30440 | G25: =D25 -> 30440
A26: 15 | B26: Pasolite Product Cat No.PD002,400mm dia/H-210 mm | C26: 3 | D26: 11160 | E26: 11160 | F26: 11160 | G26: =D26 -> 11160
B28: Supply and installation of WIPRO make Orbit Ring
B29: 800mm dia. 35-40W/ 4000K CCT.premium pendant
A30: 16 | B30: Product Cat No.LM 230R-781-xx-40-XW | C30: 1 | D30: 13185 | E30: 13185 | F30: 13185 | G30: =D30 -> 13185
B31: Supply and installation of WIPRO make Orbit 600mm
B32: dia. 20-30W/ 4000K CCT.premium pendant
A33: 17 | B33: Product Cat No.LM 230-481-xx-40-XW | C33: 1 | D33: 10900 | E33: 10900 | F33: 10900 | G33: =D33 -> 10900
B35: Supply and installation of WIPRO make SPHERE 300mm
B36: dia. premium pendant .
A37: 18 | B37: Product Cat No.LM84-D300-CRWH | C37: 5 | D37: 25425 | E37: 25425 | F37: 25425 | G37: =D37 -> 25425
B39: Supply and installation of WIPRO make TRIM LED NEO
B40: Batterns
A41: 19 | B41: WIPRO Product Cat No.LL20-111-XXX-65NE3 :- 10W | C41: 2 | D41: 910 | E41: 910 | F41: 910
A42: 29 | B42: WIPRO Product Cat No.LL20-221-XXX-65ALNE :- 20W | C42: 1 | D42: 495 | E42: 495 | F42: 495
A44: 30 | B44: Wipro make LD96-141-XXX-65-G1 Iris Neo Nextgen Square 12W light | C44: 11 | D44: 14465 | E44: 14465 | F44: 14465 | G44: =D44 -> 14465
A46: 31 | B46: Wipro make LED tracklight 36x22w 4000K | C46: 12 | D46: 70500 | E46: 70500 | F46: 70500 | G46: =D46 -> 70500
...

Sheet Light and Fitting Kochi
B2: Electricals Items
B3: Sl No | C3: Description | D3: Quantity | E3: Value | F3: Fire | G3: Burglary | H3: EEI
B4: 1 | C4: Linear light (custom made type digitech make)- Neutral white -4000k - for workstation area | D4: 26 | E4: 59800 | F4: =E4 -> 59800 | G4: =E4 -> 59800 | H4: =E4 -> 59800
B5: 2 | C5: 15W LED Down light (corvi or green make or equivalent) | D5: 3 | E5: 2655 | F5: =E5 -> 2655 | G5: =E5 -> 2655 | H5: =E5 -> 2655
B6: 3 | C6: 10 W LED Down light (corvi or green make ) | D6: 13 | E6: 10270 | F6: =E6 -> 10270 | G6: =E6 -> 10270 | H6: =E6 -> 10270
B7: 4 | C7: 6W LED Down light (corvi or green make ) | D7: 7 | E7: 4200 | F7: =E7 -> 4200 | G7: =E7 -> 4200 | H7: =E7 -> 4200
B8: 5 | C8: COB Type light fittings | D8: 10 | E8: 18000 | F8: =E8 -> 18000 | G8: =E8 -> 18000 | H8: =E8 -> 18000
B9: 6 | C9: Double light fittings | D9: 3 | E9: 5250 | F9: =E9 -> 5250 | G9: =E9 -> 5250 | H9: =E9 -> 5250
B10: 7 | C10: Spot light for reception | D10: 2 | E10: 2700 | F10: =E10 -> 2700 | G10: =E10 -> 2700 | H10: =E10 -> 2700
B11: 8 | C11: LED Tubes for cove lighting | D11: 19 | E11: 7600 | F11: =E11 -> 7600 | G11: =E11 -> 7600 | H11: =E11 -> 7600
B12: 9 | C12: Decorative hanging pendent | D12: 5 | E12: 8250 | F12: =E12 -> 8250 | G12: =E12 -> 8250 | H12: =E12 -> 8250
B13: 10 | C13: Hanging lights | D13: 9 | E13: 25200 | F13: =E13 -> 25200 | G13: =E13 -> 25200 | H13: =E13 -> 25200
B14: 11 | C14: Decorative spot light at reception | D14: 2 | E14: 3900 | F14: =E14 -> 3900 | G14: =E14 -> 3900 | H14: =E14 -> 3900
C15: Total | F15: =SUM(F4:F14) -> 147825 | G15: =SUM(G4:G14) -> 147825 | H15: =SUM(H4:H14) -> 147825

Sheet Laptops and Monitors kochi
C1: LAPTOP Description | D1: Serial Number | E1: Value | G1: Model Name | H1: Serial Number | I1: Value
A2: 1 | B2: LAPTOP | C2: Lenovo Thinkpad P1 Gen 1 ( Model: S06T00 ) | D2: R90V43E8 | E2: 88990
A3: 2 | B3: LAPTOP | C3: Asus ZenBook 14 UX434F,16GBRAM | D3: KBN0CV01A284458 | E3: 98000 | G3: Dell P2222H | H3: CN-0NYFDC-QDC00-22L-0OZU-A03 | I3: 13656.48
A4: 3 | B4: LAPTOP | C4: Lenovo Thinkpad E14 ( Model: S1XJ00 ) | D4: PG028MDY | E4: 88990 | G4: Dell P2422H | H4: CN-0NYFDC-QDC00-22L-0OTU-A03 | I4: 15500
A5: 4 | B5: LAPTOP | C5: Lenovo IdeaPad 3,11th Gen Intel Core i5,8GB | D5: PF2GRCEQ | E5: 56000 | G5: Dell P2217H | H5: CN-06N0X5-QDC00-85S-7KMU-A05 | I5: 17500
A6: 5 | B6: LAPTOP | C6: Lenovo IdeaPad 3,11th Gen Intel Core i5,8GB | D6: PF2W40W2 | E6: 56000 | G6: Dell E2421HN | H6: CN-03HYDJ-FCC00-171-CGPL-A04 | I6: 12700
A7: 6 | B7: LAPTOP | C7: Lenovo IdeaPad 3,11th Gen Intel Core i5,8GB | D7: PF30W9V4 | E7: 56000 | G7: Dell P2217H | H7: CN-06N0X5-QDC00-85T-31LU-A05 | I7: 17500
A8: 7 | B8: LAPTOP | C8: Lenovo IdeaPad 3,11th Gen Intel Core i5,8GB | D8: PF3EAGHW | E8: 56000 | G8: Dell P2417H | H8: CN-0PFR7D-74261-6BN-30LB-A00 | I8: 17500
A9: 8 | B9: LAPTOP | C9: Lenovo IdeaPad 3,11th Gen Intel Core i5,8GB | D9: PF3DWYYH | E9: 56000 | G9: Dell P2422H | H9: CN-09N16K-QDC00-2CC-4E9I-A04 | I9: 15500
A10: 9 | B10: LAPTOP | C10: Dell Inspiron E 3511 i5 512 GB,15.6FHD | D10: 4785090663 | E10: 58500 | G10: Dell P2217H | H10: CN-0M84D9-QDC00-836-2HWB-A05 | I10: 17500
A11: 10 | B11: LAPTOP | C11: Dell Vostro 3510 i5 512 GB,15.6FHD | D11: 30017440875 | E11: 58500 | G11: Dell S2216H | H11: CN-0P65TN-64180-6AO-0WHT-A00 | I11: 8600
A12: 11 | B12: LAPTOP | C12: Asus Zen Book 14 UX433FA | D12: K3N0CV07M835123 | E12: 84016 | G12: Dell E2418HN | H12: CN-07592Y-QDC00-9B5-25UB-A10 | I12: 12700
A13: 12 | B13: LAPTOP | C13: Lenovo Thinkpad E14 Gen 2 i5 512GB | D13: PG0326TK | E13: 70700 | G13: Dell S2216H | H13: CN-0VJRF7-64180-638-2SDT-A00 | I13: 8600
A14: 13 | B14: LAPTOP | C14: Lenovo Thinkpad E14 Gen 2 i5 512GB | D14: PG0327FX | E14: 70700 | G14: Dell U2718Q | H14: CN-0CDX4R-QDC00-94F-0PRL-A06 | I14: 45559
A15: 14 | B15: LAPTOP | C15: Lenovo Thinkpad E14 Gen 2 i5 512GB | D15: PG0340W8 | E15: 70700 | G15: Dell P2217 | H15: CN--0PYJDJ--TV100-01S-0XHI-A11 | I15: 17500
A16: 15 | B16: LAPTOP | C16: Lenovo Thinkpad E14 Gen 2 i5 512GB | D16: PG0340Q2 | E16: 70700 | G16: Dell P2422H | H16: CN-09N16K-QDC00-27B-0WU8-A04 | I16: 15500
A17: 16 | B17: LAPTOP | C17: Lenovo Thinkpad E14 Gen 2 i5 512GB | D17: PG034GWY | E17: 70700 | G17: Dell P2217H | H17: CN-0M84D9-QDC00-836-2HPB-A05 | I17: 17500
A18: 17 | B18: LAPTOP | C18: Lenovo Thinkpad E14 Gen 2 i5 512GB | D18: PF41N978 | E18: 70700 | G18: Dell E2421HN | H18: CN-03HYDJ-FCC00-191-C7UB-A04 | I18: 12999
A19: 18 | B19: LAPTOP | C19: Lenovo Thinkpad E14 Gen 2 i5 512GB | D19: PF41FKEM | E19: 70700 | G19: Dell E2421HN | H19: CN-03HYDJ-FCC00-17Q-AHAB-A04 | I19: 12999
A20: 19 | B20: LAPTOP | C20: Lenovo Thinkpad E14 Gen 2 i5 512GB | D20: PF41N93T | E20: 70700 | G20: Dell E2422HS | H20: CN-085JG6-FCC00-1AR-C74B-A00 | I20: 12700
A21: 20 | B21: LAPTOP | C21: Lenovo Thinkpad E14 Gen 2 i5 512GB | D21: PF41F1LD | E21: 70700 | G21: Dell P2422H | H21: CN-09N16K-QDC00-25I-93VB-A04 | I21: 15500
A22: 21 | B22: LAPTOP | C22: Lenovo Thinkpad E14 Gen 2 i5 512GB | D22: PF41F8DK | E22: 70700 | G22: Dell E2422HS | H22: CN-085JG6-FCC00-1AR-D2TB-A00 | I22: 12700
A23: 22 | B23: LAPTOP | C23: Lenovo Thinkpad E14 Gen 2 i5 512GB | D23: PF40R41L | E23: 70700 | G23: Dell E2422HS | H23: CN-085JG6-FCC00-27T-CGWB-A03 | I23: 12700
... A31: 30 | B31: LAPTOP | C31: Lenovo Thinkpad E14 Gen 4 i5 512GB | D31: PG045RZ1 | E31: 70700 | G31: Dell P2222H | H31: CN-0NYFDC-QDC00-22L-0OUU-A03 | I31: 13656.48
D32: All risk Total | E32: =SUM(E2:E31) -> 2056196 | G32: Dell SE2422H | H32: CN-0PFR7D-74261-6BN-2CAB-A00 | I32: 15500
G33: Dell P2217H | H33: CN-0PFR7D-74261-6BN-2CYB-A00 | I33: 17500
G34: Dell SE2422H | H34: CN-013V6P-FCC00-217-ACGX-A01 | I34: 15500
H35: EEI Total | I35: =SUM(I3:I34) -> 492668.96

Sheet Laptops and Monitor TVM
B1: LAPTOP Description | C1: Model | D1: Serial No. | E1: Value | H1: Model Name | I1: Serial Number | J1: Value
A2: 1 | B2: LAPTOP | C2: Apple Mac Book Air 13" | D2: SC02H904WQ6L5 | E2: 109900 | H2: Dell P2422H | I2: CN-09N16K-QDC00-3B1-7RQB | J2: 15500
A3: 2 | B3: LAPTOP | C3: Lenovo Thinkpad E15 Gen 4 i5 512GB | D3: PF48RQSW | E3: 64500 | H3: Dell P2422H | I3: CN-09N16K-QDC00-26H-7DFB-A04 | J3: 15500
A4: 3 | B4: LAPTOP | C4: Lenovo Thinkpad X1 Extreme | D4: R9-0VB1QQ | E4: 98000 | H4: Dell P2422H | I4: CN-09N16K-QDC00-2CC-4EKI-A04 | J4: 12700
A5: 4 | B5: LAPTOP | C5: Lenovo Thinkpad E14 ( Model: S1M600 ) | D5: PF23HGHT | E5: 64500 | H5: Dell E2422HS | I5: CN-085JG6-FCC00-230-DFVB-A02 | J5: 12700
A6: 5 | B6: LAPTOP | C6: Lenovo IdeaPad 3,11th Gen Intel Core i5,8GB | D6: PF2WNHBK | E6: 56000 | H6: Dell P2422H | I6: CN-09N16K-QDC00-31A-1IIU-A04 | J6: 12700
A7: 6 | B7: LAPTOP | C7: Lenovo IdeaPad 3,11th Gen Intel Core i5,8GB | D7: PF30ESQQ | E7: 56000 | H7: Dell E2422HS | I7: CN-085JG6-FCC00-29R-AEUB-A03 | J7: 12700
A8: 7 | B8: LAPTOP | C8: Lenovo IdeaPad 3,11th Gen Intel Core i5,8GB | D8: PF30YDVS | E8: 56000 | H8: Dell E2422HN | I8: CN-07D4G6-FCC00-195-ACEB-A00 | J8: 12700
A9: 8 | B9: LAPTOP | C9: Asus ZenBook 14 i7,8GB,14FHD ( UX433F ) | D9: JCN0CV11R159514 | E9: 84016 | H9: Dell P2415Q | I9: CN-0313W3-QDC00-8CG-044B-A12 | J9: 45878
A10: 9 | B10: LAPTOP | C10: Lenovo Thinkpad E14 Gen 2 i5 512GB | D10: PF46SSN4 | E10: 64500 | H10: Dell E2422HS | I10: CN-085JG6-FCC00-1AR-D2PB-A00 | J10: 12700
A11: 10 | B11: LAPTOP | C11: Lenovo IdeaPad 3,11th Gen Intel Core i5,8GB | D11: PF3530CY | E11: 56000 | H11: Dell E2422HS | I11: CN-085JG6-FCC00-1BA-C6TB-A00 | J11: 12700
A12: 11 | B12: LAPTOP | C12: Dell Inspiron E 3511 i5 16 GB,15.6FHD | D12: 11273493927 | E12: 58500 | H12: Dell P2422H | I12: CN-09N16K-QDC00-2CC-4EFI-A04 | J12: 15500
A13: 12 | B13: LAPTOP | C13: Dell Vostro 3510 i5 512 GB,15.6FHD | D13: 34189607019 | E13: 58500 | H13: Dell P2422H | I13: CN-09N16K-QDC00-26H-7S7B-A04 | J13: 15500
A14: 13 | B14: LAPTOP | C14: Lenovo Thinkpad E14 Gen 2 i5 512GB | D14: PG0326YJ | E14: 64500 | H14: Dell P2422H | I14: CN-0PFR7D-74261-6BN-3OUB-A00 | J14: 13656.48
A15: 14 | B15: LAPTOP | C15: Lenovo Thinkpad E14 Gen 2 i5 512GB | D15: PG0326T9 | E15: 64500 | H15: Dell E2418HN | I15: CN-07592Y-QDC00-89B-1L0B-A06 | J15: 12700
A16: 15 | B16: LAPTOP | C16: Lenovo Thinkpad E14 Gen 2 i5 512GB | D16: PG0327EB | E16: 64500 | H16: Dell E2421HN | I16: CN-03HYDJ-FCC00-171-CAPL-A04 | J16: 15500
A17: 16 | B17: LAPTOP | C17: Lenovo Thinkpad E14 Gen 2 i5 512GB | D17: PG0326ZD | E17: 64500 | H17: Dell E2418HN | I17: CN-07592Y-QDC00-98E-1HML-A09 | J17: 12700
A18: 17 | B18: LAPTOP | C18: Lenovo Thinkpad E14 Gen 2 i5 512GB | D18: PG0340QG | E18: 64500 | H18: Dell P2422H | I18: CN-09N16K-QDC00-27B-OE0B-A04 | J18: 15500
A19: 18 | B19: LAPTOP | C19: Lenovo Thinkpad E14 Gen 2 i5 512GB | D19: PG0340VQ | E19: 64500 | H19: Dell E2418HN | I19: CN-0DKJWG-64180-68K-03FB-A00 | J19: 12700
A20: 19 | B20: LAPTOP | C20: Lenovo Thinkpad E14 Gen 2 i5 512GB | D20: PG0340W5 | E20: 64500 | H20: Dell E2421HN | I20: CN-03HYDJ-FCC00-19M-CCWI-A04 | J20: 12700
A21: 20 | B21: LAPTOP | C21: Lenovo Thinkpad E14 Gen 2 i5 512GB | D21: PG0340W6 | E21: 64500 | H21: Dell E2421HN | I21: CN-03HYDJ-FCC00-17Q-CJWB-A04 | J21: 12700
A22: 21 | B22: LAPTOP | C22: Lenovo Thinkpad E14 Gen 2 i5 512GB | D22: PF41N992 | E22: 64500 | H22: Dell E2418HN | I22: CN-07592Y-QDC00-889-0F8L-A05 | J22: 12700
A23: 22 | B23: LAPTOP | C23: Lenovo Thinkpad E14 Gen 2 i5 512GB | D23: PF41FH67 | E23: 64500 | H23: Dell SE2422H | I23: CN-013V6P-FCC00-17T-C2UX-A01 | J23: 15500
A24: 23 | B24: LAPTOP | C24: Lenovo Thinkpad E14 Gen 2 i5 512GB | D24: PF41FEZ1 | E24: 64500 | H24: Dell SE2422H | I24: CN-013V6P-FCC00-17T-C2VX-A01 | J24: 15500
A25: 24 | B25: LAPTOP | C25: Lenovo Thinkpad E14 Gen 2 i5 512GB | D25: PF40QVCS | E25: 64500 | H25: Dell E2422HN | I25: CN-07D4G6-FCC00-195-AAFB-A00 | J25: 12700
... A36: 35 | B36: LAPTOP | C36: Lenovo IdeaPad 3,11th Gen Intel Core i5,8GB | D36: PF34RMMR | E36: 56000 | H36: Dell E2418HN | I36: CN-07592Y-QDC00-942-1P9L-A08 | J36: 12700
A37: 36 | B37: LAPTOP | C37: Lenovo Thinkpad E14 Gen 2 i5 512GB | D37: PG0340QC | E37: 70700
A38: 37 | B38: LAPTOP | C38: Lenovo IdeaPad 3,11th Gen Intel Core i5,8GB | D38: PF2VE4CP | E38: 56000 | H38: Dell P2422H | I38: CN-09N16K-QDC00-25J-4DEB-A04 | J38: 15500
A39: 38 | B39: LAPTOP | C39: Dell Inspiron 15 3000 i5 16 GB,15.6FHD | D39: 45WX3L3 | E39: 58500 | H39: Dell P2422H | I39: CN-09N16K-QDC00-31B-26YU-A04 | J39: 15500
A40: 39 | B40: LAPTOP | C40: Lenovo Thinkpad E15 Gen 4 i5 512GB | D40: PF48LT24 | E40: 70700 | H40: Dell P2422H | I40: CN-09N16K-QDC0031A-1ILU-A04 | J40: 15500
A41: 40 | B41: LAPTOP | C41: Lenovo IdeaPad 3,11th Gen Intel Core i5,8GB | D41: PF309JDG | E41: 56000 | H41: Dell P2417H | I41: CN-0VRTCJ-74261-72E-60HL-A00 | J41: 15500
A42: 41 | B42: LAPTOP | C42: Lenovo Thinkpad E14 Gen 4 i5 512GB | D42: PG03Z3CW | E42: 70700 | H42: Dell P2422H | I42: CN-09N16K-QDC00-25I-9JUB-A04 | J42: 15500
A43: 42 | B43: LAPTOP | C43: Lenovo Thinkpad E14 Gen 4 i5 512GB | D43: PG03Z3CY | E43: 70700 | H43: Dell P2422H | I43: CN-09N16K-QDC00-31A-1IGU-A04 | J43: 15500
A44: 43 | B44: LAPTOP | C44: Lenovo Thinkpad E14 Gen 4 i5 512GB | D44: PG03LR3Y | E44: 70700 | H44: Dell P2422H | I44: CN-09N16K-QDC00-319-1N5U-A04 | J44: 15500
A45: 44 | B45: LAPTOP | C45: Lenovo Thinkpad E14 Gen 4 i5 512GB | D45: PG03M3F6 | E45: 70700 | H45: Dell P2422H | I45: CN-0R5WD9-QDC00-41K-1JOL-A00 | J45: 15500
A46: 45 | B46: LAPTOP | C46: Lenovo Thinkpad E14 Gen 4 i5 512GB | D46: PG03M3PE | E46: 70700 | H46: Dell P2422H | I46: CN-0R5WD9-QDC00-41K-1JLL-A00 | J46: 15500
A47: 46 | B47: LAPTOP | C47: Lenovo Thinkpad E14 Gen 4 i5 512GB | D47: PG03M3H4 | E47: 70700 | H47: Dell P2422H | I47: CN-09N16K-QDC00-44K-1ZHU-A07 | J47: 15500
A48: 47 | B48: LAPTOP | C48: Lenovo Thinkpad E14 Gen 4 i5 512GB | D48: PG03LPGM | E48: 70700 | H48: Dell P2422H | I48: CN-0R5WD9-QDC00-41K-0RJL-A00 | J48: 15500
A49: 48 | B49: LAPTOP | C49: Lenovo Thinkpad E14 Gen 4 i5 512GB | D49: PG03LRFB | E49: 70700 | H49: Dell P2422H | I49: CN-09N16K-QDC00-44K1V7V-A07 | J49: 15500
... A67: 66 | B67: LAPTOP | C67: Lenovo Thinkpad E14 Gen 4 i5 512GB | D67: PG04JBPD | E67: 70700 | H67: Dell P2426H | I67: CN-0M3W9V-WSL00-62Q-947B-A00 | J67: 13500
...

Sheet Other Assets Items TVM
A2: PRINTERS | C2: Value | D2: Fire | E2: Burglary | F2: EEI | G2: MBD
A3: Sl No: | B3: Model
A4: 1 | B4: Epson L485 | C4: 15000 | D4: =C4 -> 15000 | E4: =C4 -> 15000 | G4: =C4 -> 15000
A5: 2 | B5: Cannon Image Class 3010 | C5: 13000 | D5: =C5 -> 13000 | E5: =C5 -> 13000 | G5: =C5 -> 13000
A6: 3 | B6: Canon Pixma G3000 All-in-One Wireless | C6: 13499 | D6: =C6 -> 13499 | E6: =C6 -> 13499 | G6: =C6 -> 13499
A7: 4 | B7: Canon Pixma G3000 All-in-One Wireless | C7: 12999 | D7: =C7 -> 12999 | E7: =C7 -> 12999 | G7: =C7 -> 12999
A8: 5 | B8: Brother DCP-L2541DW | C8: 22500 | D8: =C8 -> 22500 | E8: =C8 -> 22500 | G8: =C8 -> 22500
A10: Sl No: | B10: TV | C10: Value
A11: 1 | B11: Mi 138.8 cm (55 Inches) 4K Ultra HD Android Smart LED TV 4X | C11: 35999 | F11: =C11 -> 35999
A12: 2 | B12: VU 4K UHD 55" SMART TV | C12: 41900 | F12: =C12 -> 41900
A13: 3
A14: 4
A16: Sl No: | B16: FRIDGE | C16: Value
A17: 1 | B17: Samsung 253L Fridge ( Sam Ref RT2SA3OZSS 253L ) | C17: 22900 | D17: =C17 -> 22900 | E17: =C17 -> 22900 | G17: =C17 -> 22900
A18: 2
A20: Sl No: | B20: AC | C20: Value
A21: 1 | B21: BLUE STAR AC- 109804 | C21: 54902
A22: 2 | B22: BLUE STAR AC- 109804 | C22: 54902
D24: =SUM(D4:D18) -> 99898 | E24: =SUM(E3:E18) -> 99898 | F24: =SUM(F3:F17) -> 77899 | G24: =SUM(G3:G18) -> 99898

Sheet Other Assets Kochi
A1: CCTV
A2: Sl No | B2: Description | C2: Quantity | D2: Value | E2: Fire | F2: Burglary | G2: EEI | H2: MBD
A3: 1 | B3: 5MP DOME CAMERA | C3: 3 | D3: 6885 | E3: =D3 -> 6885 | F3: =D3 -> 6885
A4: 2 | B4: 4CH DVR WITH HARD DISK | C4: 1 | D4: 9112 | G4: =D4 -> 9112
A5: 3 | B5: BNC CONNECTOR WITH DC PIN | C5: 1 | D5: 100 | E5: =D5 -> 100 | F5: =D5 -> 100
A6: 4 | B6: CCTV CABLE 3+1 | C6: 80 | D6: 1120 | E6: =D6 -> 1120 | F6: =D6 -> 1120
A7: 5 | B7: 4 CHANNEL POWERSUPPLY | C7: 6 | D7: 5910 | E7: =D7 -> 5910 | F7: =D7 -> 5910
B8: Total | D8: =SUM(D3:D7) -> 23127
A10: BIOMETRIC ACCESS
A11: Sl No | B11: Description | C11: Quantity | D11: Value
A12: 1 | B12: ZKTECO MINIAC FACE AND PALM | C12: 2 | D12: 29200 | G12: =D12 -> 29200
A13: 2 | B13: F12 BIOMETRIC EXIT | C13: 1 | D13: 6960 | G13: =D13 -> 6960
A14: 3 | B14: DUAL EMLOCK WITH ACCESSORIES | C14: 1 | D14: 4910 | G14: =D14 -> 4910
A15: 4 | B15: U BRACKET | C15: 2 | D15: 935 | E15: =D15 -> 935 | F15: =D15 -> 935
A16: 5 | B16: L BRACKET | C16: 2 | D16: 965 | E16: =D16 -> 965 | F16: =D16 -> 965
B17: Total | D17: =SUM(D12:D16) -> 42970
A19: WIRELESS ACCESS POINT
A20: Sl No | B20: Description | C20: Quantity | D20: Value
A21: 1 | B21: EAP 225 1350MBPS CEILING MOUNT ACCESS POINT | C21: 4 | D21: 36040 | G21: =D21 -> 36040
A22: 2 | B22: CAT 6, 4 PAIR CABLE, FOR BIOMETRIC DEVICE | C22: 150mtr | D22: 4200 | E22: =D22 -> 4200 | F22: =D22 -> 4200
A23: 3 | B23: CAT 6, 1M PATCH CORD | C23: 4 | D23: 580 | E23: =D23 -> 580 | F23: =D23 -> 580
A24: 4 | B24: 8 PORT POE SWITCH | C24: 1 | D24: 13100 | G24: =D24 -> 13100
B25: Total | D25: =SUM(D21:D24) -> 53920
A27: Other Assets
A28: Sl No | B28: Description | C28: Quantity | D28: Value
A29: 1 | B29: Refrigerator | C29: 1 | D29: 25000 | E29: =D29 -> 25000 | F29: =D29 -> 25000 | H29: =D29 -> 25000
A30: 2 | B30: Microwave Oven | C30: 1 | D30: 10000 | E30: =D30 -> 10000 | F30: =D30 -> 10000 | H30: =D30 -> 10000
A31: 3 | B31: Induction stove | C31: 1 | D31: 6000 | E31: =D31 -> 6000 | F31: =D31 -> 6000 | H31: =D31 -> 6000
A32: 4 | B32: TV | C32: 2 | D32: =45000+30000 -> 75000 | G32: =D32 -> 75000
A33: 5 | B33: Printer | C33: 2 | D33: =25000+15000 -> 40000 | G33: =D33 -> 40000
A34: 6 | B34: Bean Bags | C34: 3 | D34: 20000 | E34: =H34 -> 20000 | F34: 20000 | H34: =D34 -> 20000
A35: 7 | B35: AC | C35: NA | D35: 361926 | E35: =D35 -> 361926 | F35: 361926 | H35: =D35 -> 361926
A36: 8 | B36: Fire alarm system | C36: NA | D36: 14250 | G36: =D36 -> 14250
A37: 9 | B37: AC Individual system | C37: NA | D37: 260000 | E37: =D37 -> 260000 | F37: =D37 -> 260000 | H37: =D37 -> 260000
A38: 10 | B38: Water purifier | C38: 1 | D38: 25000 | E38: =D38 -> 25000 | F38: =D38 -> 25000 | H38: =D38 -> 25000
A39: 11 | B39: Exhaust motor (Wash room) | C39: 1 | D39: 10000 | E39: =D39 -> 10000 | F39: =D39 -> 10000 | H39: =D39 -> 10000
A40: 13 | B40: Storage Rack | C40: 1 | D40: 12000 | E40: =D40 -> 12000 | F40: =D40 -> 12000
A41: 14 | B41: Vacume Cleaner | C41: 1 | D41: 10000 | E41: =D41 -> 10000 | F41: =D41 -> 10000 | H41: =D41 -> 10000
B42: Total | D42: =SUM(D29:D41) -> 869176
B44: CCTV + Biometric + Wireless + Other Assets | E44: =SUM(E29:E41) -> 739926 | F44: =SUM(F29:F41) -> 739926 | G44: =SUM(G3:G41) -> 228572 | H44: =SUM(H29:H41) -> 727926
